[2022-07-29 20:42:16,253] {taskinstance.py:1159} INFO - Dependencies all met for <TaskInstance: nse_daily_data_load.load_ftp_namedstage manual__2022-07-30T00:42:07.349428+00:00 [queued]>
[2022-07-29 20:42:16,259] {taskinstance.py:1159} INFO - Dependencies all met for <TaskInstance: nse_daily_data_load.load_ftp_namedstage manual__2022-07-30T00:42:07.349428+00:00 [queued]>
[2022-07-29 20:42:16,259] {taskinstance.py:1356} INFO - 
--------------------------------------------------------------------------------
[2022-07-29 20:42:16,259] {taskinstance.py:1357} INFO - Starting attempt 1 of 1
[2022-07-29 20:42:16,259] {taskinstance.py:1358} INFO - 
--------------------------------------------------------------------------------
[2022-07-29 20:42:16,322] {taskinstance.py:1377} INFO - Executing <Task(PythonOperator): load_ftp_namedstage> on 2022-07-30 00:42:07.349428+00:00
[2022-07-29 20:42:16,339] {standard_task_runner.py:52} INFO - Started process 345217 to run task
[2022-07-29 20:42:16,335] {standard_task_runner.py:79} INFO - Running: ['airflow', 'tasks', 'run', 'nse_daily_data_load', 'load_ftp_namedstage', 'manual__2022-07-30T00:42:07.349428+00:00', '--job-id', '69', '--raw', '--subdir', 'DAGS_FOLDER/nse_daily_load_stg.py', '--cfg-path', '/tmp/tmpqk51pd58', '--error-file', '/tmp/tmp347mtph3']
[2022-07-29 20:42:16,341] {standard_task_runner.py:80} INFO - Job 69: Subtask load_ftp_namedstage
[2022-07-29 20:42:16,454] {task_command.py:369} INFO - Running <TaskInstance: nse_daily_data_load.load_ftp_namedstage manual__2022-07-30T00:42:07.349428+00:00 [running]> on host osboxes
[2022-07-29 20:42:16,608] {taskinstance.py:1569} INFO - Exporting the following env vars:
AIRFLOW_CTX_DAG_OWNER=Airflow
AIRFLOW_CTX_DAG_ID=nse_daily_data_load
AIRFLOW_CTX_TASK_ID=load_ftp_namedstage
AIRFLOW_CTX_EXECUTION_DATE=2022-07-30T00:42:07.349428+00:00
AIRFLOW_CTX_TRY_NUMBER=1
AIRFLOW_CTX_DAG_RUN_ID=manual__2022-07-30T00:42:07.349428+00:00
[2022-07-29 20:42:16,613] {base.py:68} INFO - Using connection ID 'snowflake_conn_id' for task execution.
[2022-07-29 20:42:16,616] {connection.py:257} INFO - Snowflake Connector for Python Version: 2.7.8, Python Version: 3.8.10, Platform: Linux-5.4.0-74-generic-x86_64-with-glibc2.29
[2022-07-29 20:42:16,616] {connection.py:876} INFO - This connection is in OCSP Fail Open Mode. TLS Certificates would be checked for validity and revocation status. Any other Certificate Revocation related exceptions or OCSP Responder failures would be disregarded in favor of connectivity.
[2022-07-29 20:42:16,616] {connection.py:894} INFO - Setting use_openssl_only mode to False
[2022-07-29 20:42:18,428] {taskinstance.py:1889} ERROR - Task failed with exception
Traceback (most recent call last):
  File "/home/osboxes/.local/lib/python3.8/site-packages/airflow/operators/python.py", line 171, in execute
    return_value = self.execute_callable()
  File "/home/osboxes/.local/lib/python3.8/site-packages/airflow/operators/python.py", line 189, in execute_callable
    return self.python_callable(*self.op_args, **self.op_kwargs)
  File "/home/osboxes/airflow/dags/nse_daily_load_stg.py", line 27, in load_local_inter_stg
    res1 = ld_lcl_ins.run(sql = sql_t)
  File "/home/osboxes/.local/lib/python3.8/site-packages/airflow/providers/snowflake/hooks/snowflake.py", line 320, in run
    with closing(self.get_conn()) as conn:
  File "/home/osboxes/.local/lib/python3.8/site-packages/airflow/providers/snowflake/hooks/snowflake.py", line 259, in get_conn
    conn = connector.connect(**conn_config)
  File "/home/osboxes/.local/lib/python3.8/site-packages/snowflake/connector/__init__.py", line 51, in Connect
    return SnowflakeConnection(**kwargs)
  File "/home/osboxes/.local/lib/python3.8/site-packages/snowflake/connector/connection.py", line 279, in __init__
    self.connect(**kwargs)
  File "/home/osboxes/.local/lib/python3.8/site-packages/snowflake/connector/connection.py", line 492, in connect
    self.__open_connection()
  File "/home/osboxes/.local/lib/python3.8/site-packages/snowflake/connector/connection.py", line 731, in __open_connection
    self._authenticate(auth_instance)
  File "/home/osboxes/.local/lib/python3.8/site-packages/snowflake/connector/connection.py", line 994, in _authenticate
    self.__authenticate(self.__preprocess_auth_instance(auth_instance))
  File "/home/osboxes/.local/lib/python3.8/site-packages/snowflake/connector/connection.py", line 1014, in __authenticate
    auth.authenticate(
  File "/home/osboxes/.local/lib/python3.8/site-packages/snowflake/connector/auth.py", line 399, in authenticate
    Error.errorhandler_wrapper(
  File "/home/osboxes/.local/lib/python3.8/site-packages/snowflake/connector/errors.py", line 273, in errorhandler_wrapper
    handed_over = Error.hand_to_other_handler(
  File "/home/osboxes/.local/lib/python3.8/site-packages/snowflake/connector/errors.py", line 331, in hand_to_other_handler
    connection.errorhandler(connection, cursor, error_class, error_value)
  File "/home/osboxes/.local/lib/python3.8/site-packages/snowflake/connector/errors.py", line 207, in default_errorhandler
    raise error_class(
snowflake.connector.errors.DatabaseError: 250001 (08001): None: Failed to connect to DB: nya25226.snowflakecomputing.com:443. Incorrect username or password was specified.
[2022-07-29 20:42:18,531] {taskinstance.py:1395} INFO - Marking task as FAILED. dag_id=nse_daily_data_load, task_id=load_ftp_namedstage, execution_date=20220730T004207, start_date=20220730T004216, end_date=20220730T004218
[2022-07-29 20:42:18,641] {standard_task_runner.py:92} ERROR - Failed to execute job 69 for task load_ftp_namedstage (250001 (08001): None: Failed to connect to DB: nya25226.snowflakecomputing.com:443. Incorrect username or password was specified.; 345217)
[2022-07-29 20:42:18,692] {local_task_job.py:156} INFO - Task exited with return code 1
[2022-07-29 20:42:19,080] {local_task_job.py:273} INFO - 0 downstream tasks scheduled from follow-on schedule check
