[2022-07-31 13:37:08,757] {taskinstance.py:1159} INFO - Dependencies all met for <TaskInstance: nse_daily_data_load.nse_files_move scheduled__2022-07-30T13:22:00+00:00 [queued]>
[2022-07-31 13:37:08,762] {taskinstance.py:1159} INFO - Dependencies all met for <TaskInstance: nse_daily_data_load.nse_files_move scheduled__2022-07-30T13:22:00+00:00 [queued]>
[2022-07-31 13:37:08,763] {taskinstance.py:1356} INFO - 
--------------------------------------------------------------------------------
[2022-07-31 13:37:08,763] {taskinstance.py:1357} INFO - Starting attempt 2 of 2
[2022-07-31 13:37:08,763] {taskinstance.py:1358} INFO - 
--------------------------------------------------------------------------------
[2022-07-31 13:37:08,812] {taskinstance.py:1377} INFO - Executing <Task(PythonOperator): nse_files_move> on 2022-07-30 13:22:00+00:00
[2022-07-31 13:37:08,816] {standard_task_runner.py:52} INFO - Started process 786613 to run task
[2022-07-31 13:37:08,907] {standard_task_runner.py:79} INFO - Running: ['airflow', 'tasks', 'run', 'nse_daily_data_load', 'nse_files_move', 'scheduled__2022-07-30T13:22:00+00:00', '--job-id', '89', '--raw', '--subdir', 'DAGS_FOLDER/nse_daily_load_stg.py', '--cfg-path', '/tmp/tmpjmsscrrn', '--error-file', '/tmp/tmpwx3qpwu8']
[2022-07-31 13:37:08,912] {standard_task_runner.py:80} INFO - Job 89: Subtask nse_files_move
[2022-07-31 13:37:09,119] {task_command.py:369} INFO - Running <TaskInstance: nse_daily_data_load.nse_files_move scheduled__2022-07-30T13:22:00+00:00 [running]> on host osboxes
[2022-07-31 13:37:09,392] {taskinstance.py:1569} INFO - Exporting the following env vars:
AIRFLOW_CTX_DAG_OWNER=Airflow
AIRFLOW_CTX_DAG_ID=nse_daily_data_load
AIRFLOW_CTX_TASK_ID=nse_files_move
AIRFLOW_CTX_EXECUTION_DATE=2022-07-30T13:22:00+00:00
AIRFLOW_CTX_TRY_NUMBER=2
AIRFLOW_CTX_DAG_RUN_ID=scheduled__2022-07-30T13:22:00+00:00
[2022-07-31 13:37:09,406] {taskinstance.py:1889} ERROR - Task failed with exception
Traceback (most recent call last):
  File "/home/osboxes/.local/lib/python3.8/site-packages/airflow/operators/python.py", line 171, in execute
    return_value = self.execute_callable()
  File "/home/osboxes/.local/lib/python3.8/site-packages/airflow/operators/python.py", line 189, in execute_callable
    return self.python_callable(*self.op_args, **self.op_kwargs)
  File "/home/osboxes/airflow/dags/nse_daily_load_stg.py", line 104, in files_move_to_archives
    dt_name = datetime.datetime.now().date().strftime('%Y-%m-%d')
AttributeError: type object 'datetime.datetime' has no attribute 'datetime'
[2022-07-31 13:37:09,430] {taskinstance.py:1395} INFO - Marking task as FAILED. dag_id=nse_daily_data_load, task_id=nse_files_move, execution_date=20220730T132200, start_date=20220731T173708, end_date=20220731T173709
[2022-07-31 13:37:09,488] {standard_task_runner.py:92} ERROR - Failed to execute job 89 for task nse_files_move (type object 'datetime.datetime' has no attribute 'datetime'; 786613)
[2022-07-31 13:37:09,521] {local_task_job.py:156} INFO - Task exited with return code 1
[2022-07-31 13:37:09,589] {local_task_job.py:273} INFO - 0 downstream tasks scheduled from follow-on schedule check
