[2022-08-11 22:48:33,858] {taskinstance.py:1159} INFO - Dependencies all met for <TaskInstance: nse_daily_data_load.nse_files_move manual__2022-08-12T02:46:13.868910+00:00 [queued]>
[2022-08-11 22:48:33,904] {taskinstance.py:1159} INFO - Dependencies all met for <TaskInstance: nse_daily_data_load.nse_files_move manual__2022-08-12T02:46:13.868910+00:00 [queued]>
[2022-08-11 22:48:33,936] {taskinstance.py:1356} INFO - 
--------------------------------------------------------------------------------
[2022-08-11 22:48:33,937] {taskinstance.py:1357} INFO - Starting attempt 2 of 2
[2022-08-11 22:48:33,937] {taskinstance.py:1358} INFO - 
--------------------------------------------------------------------------------
[2022-08-11 22:48:34,052] {taskinstance.py:1377} INFO - Executing <Task(PythonOperator): nse_files_move> on 2022-08-12 02:46:13.868910+00:00
[2022-08-11 22:48:34,060] {standard_task_runner.py:52} INFO - Started process 33118 to run task
[2022-08-11 22:48:34,064] {standard_task_runner.py:79} INFO - Running: ['airflow', 'tasks', 'run', 'nse_daily_data_load', 'nse_files_move', 'manual__2022-08-12T02:46:13.868910+00:00', '--job-id', '267', '--raw', '--subdir', 'DAGS_FOLDER/nse_daily_load_stg.py', '--cfg-path', '/tmp/tmphslsam5o', '--error-file', '/tmp/tmpccqngviv']
[2022-08-11 22:48:34,081] {standard_task_runner.py:80} INFO - Job 267: Subtask nse_files_move
[2022-08-11 22:48:34,349] {task_command.py:369} INFO - Running <TaskInstance: nse_daily_data_load.nse_files_move manual__2022-08-12T02:46:13.868910+00:00 [running]> on host osboxes
[2022-08-11 22:48:34,471] {taskinstance.py:1569} INFO - Exporting the following env vars:
AIRFLOW_CTX_DAG_OWNER=Airflow
AIRFLOW_CTX_DAG_ID=nse_daily_data_load
AIRFLOW_CTX_TASK_ID=nse_files_move
AIRFLOW_CTX_EXECUTION_DATE=2022-08-12T02:46:13.868910+00:00
AIRFLOW_CTX_TRY_NUMBER=2
AIRFLOW_CTX_DAG_RUN_ID=manual__2022-08-12T02:46:13.868910+00:00
[2022-08-11 22:48:34,499] {logging_mixin.py:115} INFO - 2022-08-11
[2022-08-11 22:48:34,499] {logging_mixin.py:115} INFO - directory already available
[2022-08-11 22:48:34,499] {logging_mixin.py:115} INFO - /home/osboxes/Desktop/archives_files/2022-08-11 target file location
[2022-08-11 22:48:34,499] {logging_mixin.py:115} INFO - /home/osboxes/Desktop/Files/cm29JUL2022bhav.csv.zip 
 error identified Destination path '/home/osboxes/Desktop/archives_files/2022-08-11/cm29JUL2022bhav.csv.zip' already exists
[2022-08-11 22:48:34,501] {python.py:173} INFO - Done. Returned value was: None
[2022-08-11 22:48:34,515] {taskinstance.py:1395} INFO - Marking task as SUCCESS. dag_id=nse_daily_data_load, task_id=nse_files_move, execution_date=20220812T024613, start_date=20220812T024833, end_date=20220812T024834
[2022-08-11 22:48:34,612] {local_task_job.py:156} INFO - Task exited with return code 0
[2022-08-11 22:48:34,711] {local_task_job.py:273} INFO - 1 downstream tasks scheduled from follow-on schedule check
