[2022-08-11 21:51:43,645] {taskinstance.py:1159} INFO - Dependencies all met for <TaskInstance: nse_daily_data_load.Truncate_relaod_table scheduled__2022-08-09T13:37:00+00:00 [queued]>
[2022-08-11 21:51:43,658] {taskinstance.py:1159} INFO - Dependencies all met for <TaskInstance: nse_daily_data_load.Truncate_relaod_table scheduled__2022-08-09T13:37:00+00:00 [queued]>
[2022-08-11 21:51:43,682] {taskinstance.py:1356} INFO - 
--------------------------------------------------------------------------------
[2022-08-11 21:51:43,682] {taskinstance.py:1357} INFO - Starting attempt 1 of 1
[2022-08-11 21:51:43,683] {taskinstance.py:1358} INFO - 
--------------------------------------------------------------------------------
[2022-08-11 21:51:43,815] {taskinstance.py:1377} INFO - Executing <Task(SnowflakeOperator): Truncate_relaod_table> on 2022-08-09 13:37:00+00:00
[2022-08-11 21:51:43,832] {standard_task_runner.py:79} INFO - Running: ['airflow', 'tasks', 'run', 'nse_daily_data_load', 'Truncate_relaod_table', 'scheduled__2022-08-09T13:37:00+00:00', '--job-id', '235', '--raw', '--subdir', 'DAGS_FOLDER/nse_daily_load_stg.py', '--cfg-path', '/tmp/tmpb5_pitmm', '--error-file', '/tmp/tmp61zi4vpe']
[2022-08-11 21:51:43,849] {standard_task_runner.py:52} INFO - Started process 8536 to run task
[2022-08-11 21:51:43,865] {standard_task_runner.py:80} INFO - Job 235: Subtask Truncate_relaod_table
[2022-08-11 21:51:44,146] {task_command.py:369} INFO - Running <TaskInstance: nse_daily_data_load.Truncate_relaod_table scheduled__2022-08-09T13:37:00+00:00 [running]> on host osboxes
[2022-08-11 21:51:44,314] {taskinstance.py:1569} INFO - Exporting the following env vars:
AIRFLOW_CTX_DAG_OWNER=Airflow
AIRFLOW_CTX_DAG_ID=nse_daily_data_load
AIRFLOW_CTX_TASK_ID=Truncate_relaod_table
AIRFLOW_CTX_EXECUTION_DATE=2022-08-09T13:37:00+00:00
AIRFLOW_CTX_TRY_NUMBER=1
AIRFLOW_CTX_DAG_RUN_ID=scheduled__2022-08-09T13:37:00+00:00
[2022-08-11 21:51:44,315] {snowflake.py:118} INFO - Executing:  call EDW_DEV.EDW.LOAD_NSE_DAILY_DATA_WITH_MEASURES(); 
[2022-08-11 21:51:44,325] {base.py:68} INFO - Using connection ID 'snowflake_conn_id' for task execution.
[2022-08-11 21:51:44,329] {connection.py:257} INFO - Snowflake Connector for Python Version: 2.7.8, Python Version: 3.8.10, Platform: Linux-5.4.0-74-generic-x86_64-with-glibc2.29
[2022-08-11 21:51:44,329] {connection.py:876} INFO - This connection is in OCSP Fail Open Mode. TLS Certificates would be checked for validity and revocation status. Any other Certificate Revocation related exceptions or OCSP Responder failures would be disregarded in favor of connectivity.
[2022-08-11 21:51:44,329] {connection.py:894} INFO - Setting use_openssl_only mode to False
[2022-08-11 21:51:46,055] {cursor.py:710} INFO - query: [ALTER SESSION SET autocommit=True]
[2022-08-11 21:51:46,202] {cursor.py:734} INFO - query execution done
[2022-08-11 21:51:46,202] {snowflake.py:328} INFO - Running statement: call EDW_DEV.EDW.LOAD_NSE_DAILY_DATA_WITH_MEASURES();, parameters: None
[2022-08-11 21:51:46,203] {cursor.py:710} INFO - query: [call EDW_DEV.EDW.LOAD_NSE_DAILY_DATA_WITH_MEASURES();]
[2022-08-11 21:52:24,585] {local_task_job.py:220} WARNING - State of this instance has been externally set to None. Terminating instance.
[2022-08-11 21:52:24,686] {process_utils.py:125} INFO - Sending Signals.SIGTERM to group 8536. PIDs of all processes in the group: [8536]
[2022-08-11 21:52:24,695] {process_utils.py:80} INFO - Sending the signal Signals.SIGTERM to group 8536
[2022-08-11 21:52:24,695] {taskinstance.py:1541} ERROR - Received SIGTERM. Terminating subprocesses.
[2022-08-11 21:52:24,887] {connection.py:507} INFO - closed
[2022-08-11 21:52:26,532] {connection.py:510} INFO - No async queries seem to be running, deleting session
[2022-08-11 21:52:26,685] {taskinstance.py:1889} ERROR - Task failed with exception
Traceback (most recent call last):
  File "/home/osboxes/.local/lib/python3.8/site-packages/airflow/providers/snowflake/operators/snowflake.py", line 120, in execute
    execution_info = hook.run(self.sql, autocommit=self.autocommit, parameters=self.parameters)
  File "/home/osboxes/.local/lib/python3.8/site-packages/airflow/providers/snowflake/hooks/snowflake.py", line 332, in run
    cur.execute(sql_statement)
  File "/home/osboxes/.local/lib/python3.8/site-packages/snowflake/connector/cursor.py", line 711, in execute
    ret = self._execute_helper(query, **kwargs)
  File "/home/osboxes/.local/lib/python3.8/site-packages/snowflake/connector/cursor.py", line 511, in _execute_helper
    ret = self._connection.cmd_query(
  File "/home/osboxes/.local/lib/python3.8/site-packages/snowflake/connector/connection.py", line 954, in cmd_query
    ret = self.rest.request(
  File "/home/osboxes/.local/lib/python3.8/site-packages/snowflake/connector/network.py", line 466, in request
    return self._post_request(
  File "/home/osboxes/.local/lib/python3.8/site-packages/snowflake/connector/network.py", line 705, in _post_request
    ret = self.fetch(
  File "/home/osboxes/.local/lib/python3.8/site-packages/snowflake/connector/network.py", line 795, in fetch
    ret = self._request_exec_wrapper(
  File "/home/osboxes/.local/lib/python3.8/site-packages/snowflake/connector/network.py", line 905, in _request_exec_wrapper
    raise e
  File "/home/osboxes/.local/lib/python3.8/site-packages/snowflake/connector/network.py", line 838, in _request_exec_wrapper
    return_object = self._request_exec(
  File "/home/osboxes/.local/lib/python3.8/site-packages/snowflake/connector/network.py", line 1107, in _request_exec
    raise err
  File "/home/osboxes/.local/lib/python3.8/site-packages/snowflake/connector/network.py", line 1009, in _request_exec
    raw_ret = session.request(
  File "/home/osboxes/.local/lib/python3.8/site-packages/snowflake/connector/vendored/requests/sessions.py", line 542, in request
    resp = self.send(prep, **send_kwargs)
  File "/home/osboxes/.local/lib/python3.8/site-packages/snowflake/connector/vendored/requests/sessions.py", line 655, in send
    r = adapter.send(request, **kwargs)
  File "/home/osboxes/.local/lib/python3.8/site-packages/snowflake/connector/vendored/requests/adapters.py", line 439, in send
    resp = conn.urlopen(
  File "/home/osboxes/.local/lib/python3.8/site-packages/snowflake/connector/vendored/urllib3/connectionpool.py", line 699, in urlopen
    httplib_response = self._make_request(
  File "/home/osboxes/.local/lib/python3.8/site-packages/snowflake/connector/vendored/urllib3/connectionpool.py", line 445, in _make_request
    six.raise_from(e, None)
  File "<string>", line 3, in raise_from
  File "/home/osboxes/.local/lib/python3.8/site-packages/snowflake/connector/vendored/urllib3/connectionpool.py", line 440, in _make_request
    httplib_response = conn.getresponse()
  File "/usr/lib/python3.8/http/client.py", line 1348, in getresponse
    response.begin()
  File "/usr/lib/python3.8/http/client.py", line 316, in begin
    version, status, reason = self._read_status()
  File "/usr/lib/python3.8/http/client.py", line 277, in _read_status
    line = str(self.fp.readline(_MAXLINE + 1), "iso-8859-1")
  File "/usr/lib/python3.8/socket.py", line 669, in readinto
    return self._sock.recv_into(b)
  File "/home/osboxes/.local/lib/python3.8/site-packages/snowflake/connector/vendored/urllib3/contrib/pyopenssl.py", line 331, in recv_into
    if not util.wait_for_read(self.socket, self.socket.gettimeout()):
  File "/home/osboxes/.local/lib/python3.8/site-packages/snowflake/connector/vendored/urllib3/util/wait.py", line 146, in wait_for_read
    return wait_for_socket(sock, read=True, timeout=timeout)
  File "/home/osboxes/.local/lib/python3.8/site-packages/snowflake/connector/vendored/urllib3/util/wait.py", line 107, in poll_wait_for_socket
    return bool(_retry_on_intr(do_poll, timeout))
  File "/home/osboxes/.local/lib/python3.8/site-packages/snowflake/connector/vendored/urllib3/util/wait.py", line 43, in _retry_on_intr
    return fn(timeout)
  File "/home/osboxes/.local/lib/python3.8/site-packages/snowflake/connector/vendored/urllib3/util/wait.py", line 105, in do_poll
    return poll_obj.poll(t)
  File "/home/osboxes/.local/lib/python3.8/site-packages/airflow/models/taskinstance.py", line 1543, in signal_handler
    raise AirflowException("Task received SIGTERM signal")
airflow.exceptions.AirflowException: Task received SIGTERM signal
[2022-08-11 21:52:26,698] {taskinstance.py:1395} INFO - Marking task as FAILED. dag_id=nse_daily_data_load, task_id=Truncate_relaod_table, execution_date=20220809T133700, start_date=20220812T015143, end_date=20220812T015226
[2022-08-11 21:52:26,845] {standard_task_runner.py:92} ERROR - Failed to execute job 235 for task Truncate_relaod_table (Task received SIGTERM signal; 8536)
[2022-08-11 21:52:26,881] {process_utils.py:75} INFO - Process psutil.Process(pid=8536, status='terminated', exitcode=1, started='21:51:43') (8536) terminated with exit code 1
