[2022-08-11 22:32:53,102] {taskinstance.py:1159} INFO - Dependencies all met for <TaskInstance: nse_daily_data_load.nse_files_move scheduled__2022-08-10T13:37:00+00:00 [queued]>
[2022-08-11 22:32:53,110] {taskinstance.py:1159} INFO - Dependencies all met for <TaskInstance: nse_daily_data_load.nse_files_move scheduled__2022-08-10T13:37:00+00:00 [queued]>
[2022-08-11 22:32:53,137] {taskinstance.py:1356} INFO - 
--------------------------------------------------------------------------------
[2022-08-11 22:32:53,137] {taskinstance.py:1357} INFO - Starting attempt 3 of 3
[2022-08-11 22:32:53,137] {taskinstance.py:1358} INFO - 
--------------------------------------------------------------------------------
[2022-08-11 22:32:53,235] {taskinstance.py:1377} INFO - Executing <Task(PythonOperator): nse_files_move> on 2022-08-10 13:37:00+00:00
[2022-08-11 22:32:53,238] {standard_task_runner.py:52} INFO - Started process 19216 to run task
[2022-08-11 22:32:53,253] {standard_task_runner.py:79} INFO - Running: ['airflow', 'tasks', 'run', 'nse_daily_data_load', 'nse_files_move', 'scheduled__2022-08-10T13:37:00+00:00', '--job-id', '247', '--raw', '--subdir', 'DAGS_FOLDER/nse_daily_load_stg.py', '--cfg-path', '/tmp/tmpn85aji2h', '--error-file', '/tmp/tmpa82yqild']
[2022-08-11 22:32:53,255] {standard_task_runner.py:80} INFO - Job 247: Subtask nse_files_move
[2022-08-11 22:32:53,368] {task_command.py:369} INFO - Running <TaskInstance: nse_daily_data_load.nse_files_move scheduled__2022-08-10T13:37:00+00:00 [running]> on host osboxes
[2022-08-11 22:32:53,531] {taskinstance.py:1569} INFO - Exporting the following env vars:
AIRFLOW_CTX_DAG_OWNER=Airflow
AIRFLOW_CTX_DAG_ID=nse_daily_data_load
AIRFLOW_CTX_TASK_ID=nse_files_move
AIRFLOW_CTX_EXECUTION_DATE=2022-08-10T13:37:00+00:00
AIRFLOW_CTX_TRY_NUMBER=3
AIRFLOW_CTX_DAG_RUN_ID=scheduled__2022-08-10T13:37:00+00:00
[2022-08-11 22:32:53,541] {taskinstance.py:1889} ERROR - Task failed with exception
Traceback (most recent call last):
  File "/home/osboxes/.local/lib/python3.8/site-packages/airflow/operators/python.py", line 171, in execute
    return_value = self.execute_callable()
  File "/home/osboxes/.local/lib/python3.8/site-packages/airflow/operators/python.py", line 189, in execute_callable
    return self.python_callable(*self.op_args, **self.op_kwargs)
  File "/home/osboxes/airflow/dags/nse_daily_load_stg.py", line 140, in files_move_to_archives
    cleat_curr_dir_files();
  File "/home/osboxes/airflow/dags/nse_daily_load_stg.py", line 33, in cleat_curr_dir_files
    dt_name = datetime.datetime.now().date().strftime('%Y-%m-%d')
AttributeError: type object 'datetime.datetime' has no attribute 'datetime'
[2022-08-11 22:32:53,555] {taskinstance.py:1395} INFO - Marking task as FAILED. dag_id=nse_daily_data_load, task_id=nse_files_move, execution_date=20220810T133700, start_date=20220812T023253, end_date=20220812T023253
[2022-08-11 22:32:53,614] {standard_task_runner.py:92} ERROR - Failed to execute job 247 for task nse_files_move (type object 'datetime.datetime' has no attribute 'datetime'; 19216)
[2022-08-11 22:32:53,633] {local_task_job.py:156} INFO - Task exited with return code 1
[2022-08-11 22:32:53,723] {local_task_job.py:273} INFO - 0 downstream tasks scheduled from follow-on schedule check
