[2022-08-11 22:29:46,490] {taskinstance.py:1159} INFO - Dependencies all met for <TaskInstance: nse_daily_data_load.load_ftp_namedstage scheduled__2022-08-10T13:37:00+00:00 [queued]>
[2022-08-11 22:29:46,544] {taskinstance.py:1159} INFO - Dependencies all met for <TaskInstance: nse_daily_data_load.load_ftp_namedstage scheduled__2022-08-10T13:37:00+00:00 [queued]>
[2022-08-11 22:29:46,584] {taskinstance.py:1356} INFO - 
--------------------------------------------------------------------------------
[2022-08-11 22:29:46,584] {taskinstance.py:1357} INFO - Starting attempt 2 of 2
[2022-08-11 22:29:46,584] {taskinstance.py:1358} INFO - 
--------------------------------------------------------------------------------
[2022-08-11 22:29:46,761] {taskinstance.py:1377} INFO - Executing <Task(PythonOperator): load_ftp_namedstage> on 2022-08-10 13:37:00+00:00
[2022-08-11 22:29:46,764] {standard_task_runner.py:52} INFO - Started process 16932 to run task
[2022-08-11 22:29:46,839] {standard_task_runner.py:79} INFO - Running: ['airflow', 'tasks', 'run', 'nse_daily_data_load', 'load_ftp_namedstage', 'scheduled__2022-08-10T13:37:00+00:00', '--job-id', '246', '--raw', '--subdir', 'DAGS_FOLDER/nse_daily_load_stg.py', '--cfg-path', '/tmp/tmpzl0kzd03', '--error-file', '/tmp/tmpblw37apr']
[2022-08-11 22:29:46,879] {standard_task_runner.py:80} INFO - Job 246: Subtask load_ftp_namedstage
[2022-08-11 22:29:47,176] {task_command.py:369} INFO - Running <TaskInstance: nse_daily_data_load.load_ftp_namedstage scheduled__2022-08-10T13:37:00+00:00 [running]> on host osboxes
[2022-08-11 22:29:47,281] {taskinstance.py:1569} INFO - Exporting the following env vars:
AIRFLOW_CTX_DAG_OWNER=Airflow
AIRFLOW_CTX_DAG_ID=nse_daily_data_load
AIRFLOW_CTX_TASK_ID=load_ftp_namedstage
AIRFLOW_CTX_EXECUTION_DATE=2022-08-10T13:37:00+00:00
AIRFLOW_CTX_TRY_NUMBER=2
AIRFLOW_CTX_DAG_RUN_ID=scheduled__2022-08-10T13:37:00+00:00
[2022-08-11 22:29:47,285] {taskinstance.py:1889} ERROR - Task failed with exception
Traceback (most recent call last):
  File "/home/osboxes/.local/lib/python3.8/site-packages/airflow/operators/python.py", line 171, in execute
    return_value = self.execute_callable()
  File "/home/osboxes/.local/lib/python3.8/site-packages/airflow/operators/python.py", line 189, in execute_callable
    return self.python_callable(*self.op_args, **self.op_kwargs)
  File "/home/osboxes/airflow/dags/nse_daily_load_stg.py", line 68, in load_local_inter_stg
    cleat_curr_dir_files()
  File "/home/osboxes/airflow/dags/nse_daily_load_stg.py", line 33, in cleat_curr_dir_files
    dt_name = datetime.datetime.now().date().strftime('%Y-%m-%d')
AttributeError: type object 'datetime.datetime' has no attribute 'datetime'
[2022-08-11 22:29:47,296] {taskinstance.py:1395} INFO - Marking task as FAILED. dag_id=nse_daily_data_load, task_id=load_ftp_namedstage, execution_date=20220810T133700, start_date=20220812T022946, end_date=20220812T022947
[2022-08-11 22:29:47,332] {standard_task_runner.py:92} ERROR - Failed to execute job 246 for task load_ftp_namedstage (type object 'datetime.datetime' has no attribute 'datetime'; 16932)
[2022-08-11 22:29:47,347] {local_task_job.py:156} INFO - Task exited with return code 1
[2022-08-11 22:29:47,396] {local_task_job.py:273} INFO - 0 downstream tasks scheduled from follow-on schedule check
